<?xml version="1.0" encoding="UTF-8"?>
<!-- Generated by org.testng.reporters.JUnitReportReporter -->
<testsuite hostname="ajay-PC" name="Scenario_Component.Scenario_Login" tests="8" failures="0" timestamp="15 May 2018 05:36:59 GMT" time="83.940" errors="1">
  <testcase name="testInvalidlogin" time="8.792" classname="Scenario_Component.Scenario_Login"/>
  <testcase name="testValidlogin" time="12.410" classname="Scenario_Component.Scenario_Login"/>
  <testcase name="testInvalidlogin" time="10.236" classname="Scenario_Component.Scenario_Login"/>
  <testcase name="testInvalidlogin" time="10.170" classname="Scenario_Component.Scenario_Login"/>
  <testcase name="testInvalidlogin" time="7.908" classname="Scenario_Component.Scenario_Login"/>
  <testcase name="testValidlogin" time="13.941" classname="Scenario_Component.Scenario_Login">
    <error type="java.lang.AssertionError" message="The following asserts failed:
null">
      <![CDATA[java.lang.AssertionError: The following asserts failed:
null
	at org.testng.asserts.SoftAssert.assertAll(SoftAssert.java:37)
	at Scenario_Component.Scenario_Login.testValidlogin(Scenario_Login.java:89)
	at sun.reflect.NativeMethodAccessorImpl.invoke0(Native Method)
	at sun.reflect.NativeMethodAccessorImpl.invoke(Unknown Source)
	at sun.reflect.DelegatingMethodAccessorImpl.invoke(Unknown Source)
	at java.lang.reflect.Method.invoke(Unknown Source)
	at org.testng.internal.MethodInvocationHelper.invokeMethod(MethodInvocationHelper.java:80)
	at org.testng.internal.Invoker.invokeMethod(Invoker.java:714)
	at org.testng.internal.Invoker.invokeTestMethod(Invoker.java:901)
	at org.testng.internal.Invoker.invokeTestMethods(Invoker.java:1231)
	at org.testng.internal.TestMethodWorker.invokeTestMethods(TestMethodWorker.java:127)
	at org.testng.internal.TestMethodWorker.run(TestMethodWorker.java:111)
	at org.testng.TestRunner.privateRun(TestRunner.java:767)
	at org.testng.TestRunner.run(TestRunner.java:617)
	at org.testng.SuiteRunner.runTest(SuiteRunner.java:334)
	at org.testng.SuiteRunner.runSequentially(SuiteRunner.java:329)
	at org.testng.SuiteRunner.privateRun(SuiteRunner.java:291)
	at org.testng.SuiteRunner.run(SuiteRunner.java:240)
	at org.testng.SuiteRunnerWorker.runSuite(SuiteRunnerWorker.java:52)
	at org.testng.SuiteRunnerWorker.run(SuiteRunnerWorker.java:86)
	at org.testng.TestNG.runSuitesSequentially(TestNG.java:1198)
	at org.testng.TestNG.runSuitesLocally(TestNG.java:1123)
	at org.testng.TestNG.run(TestNG.java:1031)
	at org.testng.remote.AbstractRemoteTestNG.run(AbstractRemoteTestNG.java:114)
	at org.testng.remote.RemoteTestNG.initAndRun(RemoteTestNG.java:251)
	at org.testng.remote.RemoteTestNG.main(RemoteTestNG.java:77)
]]>
    </error>
  </testcase> <!-- testValidlogin -->
  <testcase name="testInvalidlogin" time="10.735" classname="Scenario_Component.Scenario_Login"/>
  <testcase name="testInvalidlogin" time="9.748" classname="Scenario_Component.Scenario_Login"/>
</testsuite> <!-- Scenario_Component.Scenario_Login -->
